<?xml version="1.0" ?>
<!-- ROS2 Control Hardware Plugin for BrickPi3 -->
<robot name="mike">
  <link name="base_link"></link>
  <link name="front_left_wheel"></link>
  <link name="front_right_wheel"></link>
  <link name="rear_left_wheel"></link>
  <link name="rear_right_wheel"></link>
  <joint name="PORT_C" type="continuous">
    <parent link="base_link"/>
    <child link="front_left_wheel"/>
  </joint>
  <joint name="PORT_D" type="continuous">
    <parent link="base_link"/>
    <child link="front_right_wheel"/>
  </joint>
  <joint name="PORT_B" type="continuous">
    <parent link="base_link"/>
    <child link="rear_left_wheel"/>
  </joint>
  <joint name="PORT_A" type="continuous">
    <parent link="base_link"/>
    <child link="rear_right_wheel"/>
  </joint>
  <ros2_control name="BrickPi3" type="system">
    <hardware>
      <plugin>brickpi3_motors/BrickPi3MotorsHardware</plugin>
      <param name="hw_start_duration_sec">0</param>
      <param name="hw_stop_duration_sec">3.0</param>
    </hardware>
    <joint name="PORT_C">
      <command_interface name="velocity"/>
      <state_interface name="position"/>
      <state_interface name="velocity"/>
    </joint>
    <joint name="PORT_D">
      <command_interface name="velocity"/>
      <state_interface name="position"/>
      <state_interface name="velocity"/>
    </joint>
    <joint name="PORT_B">
      <command_interface name="velocity"/>
      <state_interface name="position"/>
      <state_interface name="velocity"/>
    </joint>
    <joint name="PORT_A">
      <command_interface name="velocity"/>
      <state_interface name="position"/>
      <state_interface name="velocity"/>
    </joint>
  </ros2_control>
</robot>
